<mujoco model="arm3d">

    <option gravity="0 0 0"/>

    <worldbody>

        <body name="base"
              pos="0 0 0">

            <joint
                name="joint1"
                type="hinge"
                axis="0 0 1"/>

            <geom
                type="capsule"
                fromto="0 0 0 0.5 0 0"
                size="0.04"/>

            <body pos="0.5 0 0">

                <joint
                    name="joint2"
                    type="hinge"
                    axis="0 1 0"/>

                <geom
                    type="capsule"
                    fromto="0 0 0 0.4 0 0"
                    size="0.035"/>

                <body pos="0.4 0 0">

                    <joint
                        name="joint3"
                        type="hinge"
                        axis="0 1 0"/>

                    <geom
                        type="capsule"
                        fromto="0 0 0 0.3 0 0"
                        size="0.03"/>

                    <site
                        name="ee"
                        pos="0.3 0 0"
                        size="0.03"/>

                </body>

            </body>

        </body>

        <body name="target" pos="0.8 0.2 -0.3">

            <geom
                type="sphere"
                size="0.04"
                rgba="1 0 0 1"/>

        </body>

    </worldbody>

</mujoco>